<?xml version="1.0" encoding="utf-8"?>
<!-- This URDF was automatically created by SolidWorks to URDF Exporter! Originally created by Stephen Brawner (brawner@gmail.com) 
     Commit Version: 1.6.0-4-g7f85cfe  Build Version: 1.6.7995.38578
     For more information, please see http://wiki.ros.org/sw_urdf_exporter -->
<robot
  name="Final_Assembly.SLDASM">
  <link
    name="base_link">
    <inertial>
      <origin
        xyz="6.9038E-05 0.012473 -0.002324"
        rpy="0 0 0" />
      <mass
        value="0.27541" />
      <inertia
        ixx="0.0004016"
        ixy="1.0222E-07"
        ixz="5.5689E-07"
        iyy="0.0023016"
        iyz="-1.0632E-05"
        izz="0.0019886" />
    </inertial>
    <visual>
      <origin
        xyz="0 0 0"
        rpy="0 0 0" />
      <geometry>
        <mesh
          filename="package://Final_Assembly.SLDASM/meshes/base_link.STL" />
      </geometry>
      <material
        name="">
        <color
          rgba="0.79216 0.81961 0.93333 1" />
      </material>
    </visual>
    <collision>
      <origin
        xyz="0 0 0"
        rpy="0 0 0" />
      <geometry>
        <mesh
          filename="package://Final_Assembly.SLDASM/meshes/base_link.STL" />
      </geometry>
    </collision>
  </link>
  <link
    name="claw2">
    <inertial>
      <origin
        xyz="0.0094684 0.017527 0.020737"
        rpy="0 0 0" />
      <mass
        value="0.11801" />
      <inertia
        ixx="3.9078E-05"
        ixy="1.0048E-06"
        ixz="3.4643E-06"
        iyy="4.9475E-05"
        iyz="4.7534E-07"
        izz="3.1211E-05" />
    </inertial>
    <visual>
      <origin
        xyz="0 0 0"
        rpy="0 0 0" />
      <geometry>
        <mesh
          filename="package://Final_Assembly.SLDASM/meshes/claw2.STL" />
      </geometry>
      <material
        name="">
        <color
          rgba="0.79216 0.81961 0.93333 1" />
      </material>
    </visual>
    <collision>
      <origin
        xyz="0 0 0"
        rpy="0 0 0" />
      <geometry>
        <mesh
          filename="package://Final_Assembly.SLDASM/meshes/claw2.STL" />
      </geometry>
    </collision>
  </link>
  <joint
    name="claw2translation"
    type="prismatic">
    <origin
      xyz="-0.068604 0.040444 -0.021092"
      rpy="0 0 0" />
    <parent
      link="base_link" />
    <child
      link="claw2" />
    <axis
      xyz="1 0 0" />
    <limit
      lower="0"
      upper="0.04"
      effort="10"
      velocity="10" />
    <dynamics
      damping="0.1"
      friction="0.1" />
  </joint>
  <link
    name="claw1">
    <inertial>
      <origin
        xyz="6.9038E-05 0.012473 -0.002324"
        rpy="0 0 0" />
      <mass
        value="0.11801" />
      <inertia
        ixx="0.0004016"
        ixy="1.0222E-07"
        ixz="5.5689E-07"
        iyy="0.0023016"
        iyz="-1.0632E-05"
        izz="0.0019886" />
    </inertial>
    <visual>
      <origin
        xyz="0 0 0"
        rpy="0 0 0" />
      <geometry>
        <mesh
          filename="package://Final_Assembly.SLDASM/meshes/claw1.STL" />
      </geometry>
      <material
        name="">
        <color
          rgba="0.79216 0.81961 0.93333 1" />
      </material>
    </visual>
    <collision>
      <origin
        xyz="0 0 0"
        rpy="0 0 0" />
      <geometry>
        <mesh
          filename="package://Final_Assembly.SLDASM/meshes/claw1.STL" />
      </geometry>
    </collision>
  </link>
  <joint
    name="claw1translation"
    type="prismatic">
    <origin
      xyz="0.060537 0.040444 0.019491"
      rpy="3.1416 0 3.1416" />
    <parent
      link="base_link" />
    <child
      link="claw1" />
    <axis
      xyz="-1 0 0" />
    <limit
      lower="0"
      upper="0.04"
      effort="10"
      velocity="10" />
    <dynamics
      damping="0.1"
      friction="0.1" />
  </joint>
</robot>